<?xml version="1.0" encoding="utf-8"?>
<!-- This URDF was automatically created by SolidWorks to URDF Exporter! Originally created by Stephen Brawner (brawner@gmail.com) 
     Commit Version: 1.6.0-1-g15f4949  Build Version: 1.6.7594.29634
     For more information, please see http://wiki.ros.org/sw_urdf_exporter -->
<robot
  name="robotic_arm_description">
  <link
    name="base_link">
    <inertial>
      <origin
        xyz="-4.4033E-05 -9.2364E-09 0.0091905"
        rpy="0 0 0" />
      <mass
        value="0.13522" />
      <inertia
        ixx="8.2338E-05"
        ixy="7.4498E-12"
        ixz="-5.8286E-08"
        iyy="8.2221E-05"
        iyz="-3.4309E-12"
        izz="0.00016141" />
    </inertial>
    <visual>
      <origin
        xyz="0 0 0"
        rpy="0 0 0" />
      <geometry>
        <mesh
          filename="package://robotic_arm_description/meshes/base_link.STL" />
      </geometry>
      <material
        name="">
        <color
          rgba="0.79216 0.81961 0.93333 1" />
      </material>
    </visual>
    <collision>
      <origin
        xyz="0 0 0"
        rpy="0 0 0" />
      <geometry>
        <mesh
          filename="package://robotic_arm_description/meshes/base_link.STL" />
      </geometry>
    </collision>
  </link>
  <link
    name="link_1">
    <inertial>
      <origin
        xyz="-0.00012346 0.0054526 0.027055"
        rpy="0 0 0" />
      <mass
        value="0.050412" />
      <inertia
        ixx="1.5547E-05"
        ixy="-9.7433E-09"
        ixz="-3.2877E-10"
        iyy="1.8456E-05"
        iyz="-3.4308E-12"
        izz="2.6201E-05" />
    </inertial>
    <visual>
      <origin
        xyz="0 0 0"
        rpy="0 0 0" />
      <geometry>
        <mesh
          filename="package://robotic_arm_description/meshes/link_1.STL" />
      </geometry>
      <material
        name="">
        <color
          rgba="0.79216 0.81961 0.93333 1" />
      </material>
    </visual>
    <collision>
      <origin
        xyz="0 0 0"
        rpy="0 0 0" />
      <geometry>
        <mesh
          filename="package://robotic_arm_description/meshes/link_1.STL" />
      </geometry>
    </collision>
  </link>
  <joint
    name="joint_1"
    type="continuous">
    <origin
      xyz="0 0 0.0205"
      rpy="0 0 0" />
    <parent
      link="base_link" />
    <child
      link="link_1" />
    <axis
      xyz="0 0 -1" />
  </joint>
  <link
    name="link_2">
    <inertial>
      <origin
        xyz="0.033324 0.0051435 0.026957"
        rpy="0 0 0" />
      <mass
        value="0.019226" />
      <inertia
        ixx="1.161E-05"
        ixy="3.9949E-07"
        ixz="-3.1029E-06"
        iyy="7.5692E-06"
        iyz="2.9193E-07"
        izz="1.2914E-05" />
    </inertial>
    <visual>
      <origin
        xyz="0 0 0"
        rpy="0 0 0" />
      <geometry>
        <mesh
          filename="package://robotic_arm_description/meshes/link_2.STL" />
      </geometry>
      <material
        name="">
        <color
          rgba="0.79216 0.81961 0.93333 1" />
      </material>
    </visual>
    <collision>
      <origin
        xyz="0 0 0"
        rpy="0 0 0" />
      <geometry>
        <mesh
          filename="package://robotic_arm_description/meshes/link_2.STL" />
      </geometry>
    </collision>
  </link>
  <joint
    name="joint_2"
    type="continuous">
    <origin
      xyz="-0.00515 0 0.04435"
      rpy="0 0 0" />
    <parent
      link="link_1" />
    <child
      link="link_2" />
    <axis
      xyz="0 -1 0" />
  </joint>
  <link
    name="link_3">
    <inertial>
      <origin
        xyz="0.041207 -0.0014508 -0.01416"
        rpy="0 0 0" />
      <mass
        value="0.014517" />
      <inertia
        ixx="4.2489E-06"
        ixy="3.2512E-07"
        ixz="9.9511E-07"
        iyy="3.8216E-06"
        iyz="-1.1177E-07"
        izz="6.8027E-06" />
    </inertial>
    <visual>
      <origin
        xyz="0 0 0"
        rpy="0 0 0" />
      <geometry>
        <mesh
          filename="package://robotic_arm_description/meshes/link_3.STL" />
      </geometry>
      <material
        name="">
        <color
          rgba="0.79216 0.81961 0.93333 1" />
      </material>
    </visual>
    <collision>
      <origin
        xyz="0 0 0"
        rpy="0 0 0" />
      <geometry>
        <mesh
          filename="package://robotic_arm_description/meshes/link_3.STL" />
      </geometry>
    </collision>
  </link>
  <joint
    name="joint_3"
    type="continuous">
    <origin
      xyz="0.051117 0 0.04015"
      rpy="0 0 0" />
    <parent
      link="link_2" />
    <child
      link="link_3" />
    <axis
      xyz="0 -1 0" />
  </joint>
  <link
    name="end_effector">
    <inertial>
      <origin
        xyz="0.00022284 -0.020701 -0.014202"
        rpy="0 0 0" />
      <mass
        value="0.015554" />
      <inertia
        ixx="3.0068E-06"
        ixy="-1.0568E-08"
        ixz="2.0515E-07"
        iyy="1.7554E-06"
        iyz="-2.5581E-09"
        izz="1.8545E-06" />
    </inertial>
    <visual>
      <origin
        xyz="0 0 0"
        rpy="0 0 0" />
      <geometry>
        <mesh
          filename="package://robotic_arm_description/meshes/end_effector.STL" />
      </geometry>
      <material
        name="">
        <color
          rgba="0.79216 0.81961 0.93333 1" />
      </material>
    </visual>
    <collision>
      <origin
        xyz="0 0 0"
        rpy="0 0 0" />
      <geometry>
        <mesh
          filename="package://robotic_arm_description/meshes/end_effector.STL" />
      </geometry>
    </collision>
  </link>
  <joint
    name="joint_4"
    type="continuous">
    <origin
      xyz="0.058386 0 -0.02"
      rpy="0 0 0" />
    <parent
      link="link_3" />
    <child
      link="end_effector" />
    <axis
      xyz="0 -1 0" />
  </joint>
  <link
    name="gripper">
    <inertial>
      <origin
        xyz="0.01753 -0.0022519 -0.0070303"
        rpy="0 0 0" />
      <mass
        value="0.0008242" />
      <inertia
        ixx="3.0387E-08"
        ixy="-2.3851E-23"
        ixz="5.8982E-23"
        iyy="1.7833E-08"
        iyz="-3.6695E-10"
        izz="1.3103E-08" />
    </inertial>
    <visual>
      <origin
        xyz="0 0 0"
        rpy="0 0 0" />
      <geometry>
        <mesh
          filename="package://robotic_arm_description/meshes/gripper.STL" />
      </geometry>
      <material
        name="">
        <color
          rgba="0.79216 0.81961 0.93333 1" />
      </material>
    </visual>
    <collision>
      <origin
        xyz="0 0 0"
        rpy="0 0 0" />
      <geometry>
        <mesh
          filename="package://robotic_arm_description/meshes/gripper.STL" />
      </geometry>
    </collision>
  </link>
  <joint
    name="joint_5"
    type="continuous">
    <origin
      xyz="0 -0.015925 -0.01717"
      rpy="0 0 0" />
    <parent
      link="end_effector" />
    <child
      link="gripper" />
    <axis
      xyz="-1 0 0" />
  </joint>
</robot>