<?xml version="1.0" encoding="utf-8"?>
<!-- This URDF was automatically created by SolidWorks to URDF Exporter! Originally created by Stephen Brawner (brawner@gmail.com) 
     Commit Version: 1.6.0-1-g15f4949  Build Version: 1.6.7594.29634
     For more information, please see http://wiki.ros.org/sw_urdf_exporter -->
<robot
  name="robotic_arm_description">
  <link name="world"/>
  <joint name="world_to_base_link=" type="fixed">
     <parent link="world"/>
     <child link="base_link"/>
</joint>
  <link
    name="base_link">
    <inertial>
      <origin
        xyz="-4.4033E-05 -9.2364E-09 0.0091905"
        rpy="0 0 0" />
      <mass
        value="0.13522" />
      <inertia
        ixx="8.2338E-05"
        ixy="7.4498E-12"
        ixz="-5.8286E-08"
        iyy="8.2221E-05"
        iyz="-3.4309E-12"
        izz="0.00016141" />
    </inertial>
    <visual>
      <origin
        xyz="0 0 0"
        rpy="0 0 0" />
      <geometry>
        <mesh
          filename="package://robotic_arm_description/meshes/base_link.STL" />
      </geometry>
      <material
        name="">
        <color
          rgba="0.79216 0.81961 0.93333 1" />
      </material>
    </visual>
    <collision>
      <origin
        xyz="0 0 0"
        rpy="0 0 0" />
      <geometry>
        <mesh
          filename="package://robotic_arm_description/meshes/base_link.STL" />
      </geometry>
    </collision>
  </link>
  <link
    name="link_1">
    <inertial>
      <origin
        xyz="-0.00012346 0.0054526 0.027055"
        rpy="0 0 0" />
      <mass
        value="0.050412" />
      <inertia
        ixx="1.5547E-05"
        ixy="-9.7433E-09"
        ixz="-3.2877E-10"
        iyy="1.8456E-05"
        iyz="-3.4308E-12"
        izz="2.6201E-05" />
    </inertial>
    <visual>
      <origin
        xyz="0 0 0"
        rpy="0 0 0" />
      <geometry>
        <mesh
          filename="package://robotic_arm_description/meshes/link_1.STL" />
      </geometry>
      <material
        name="">
        <color
          rgba="0.79216 0.81961 0.93333 1" />
      </material>
    </visual>
    <collision>
      <origin
        xyz="0 0 0"
        rpy="0 0 0" />
      <geometry>
        <mesh
          filename="package://robotic_arm_description/meshes/link_1.STL" />
      </geometry>
    </collision>
  </link>
  <joint
    name="joint_1"
    type="continuous">
    <origin
      xyz="0 0 0.0205"
      rpy="0 0 0" />
    <parent
      link="base_link" />
    <child
      link="link_1" />
    <axis
      xyz="0 0 -1" />
  </joint>
  <link
    name="link_2">
    <inertial>
      <origin
        xyz="0.033324 0.0051435 0.026957"
        rpy="0 0 0" />
      <mass
        value="0.019226" />
      <inertia
        ixx="1.161E-05"
        ixy="3.9949E-07"
        ixz="-3.1029E-06"
        iyy="7.5692E-06"
        iyz="2.9193E-07"
        izz="1.2914E-05" />
    </inertial>
    <visual>
      <origin
        xyz="0 0 0"
        rpy="0 0 0" />
      <geometry>
        <mesh
          filename="package://robotic_arm_description/meshes/link_2.STL" />
      </geometry>
      <material
        name="">
        <color
          rgba="0.79216 0.81961 0.93333 1" />
      </material>
    </visual>
    <collision>
      <origin
        xyz="0 0 0"
        rpy="0 0 0" />
      <geometry>
        <mesh
          filename="package://robotic_arm_description/meshes/link_2.STL" />
      </geometry>
    </collision>
  </link>
  <joint
    name="joint_2"
    type="continuous">
    <origin
      xyz="-0.00515 0 0.04435"
      rpy="0 0 0" />
    <parent
      link="link_1" />
    <child
      link="link_2" />
    <axis
      xyz="0 -1 0" />
  </joint>
  <link
    name="link_3">
    <inertial>
      <origin
        xyz="0.041207 -0.0014508 -0.01416"
        rpy="0 0 0" />
      <mass
        value="0.014517" />
      <inertia
        ixx="4.2489E-06"
        ixy="3.2512E-07"
        ixz="9.9511E-07"
        iyy="3.8216E-06"
        iyz="-1.1177E-07"
        izz="6.8027E-06" />
    </inertial>
    <visual>
      <origin
        xyz="0 0 0"
        rpy="0 0 0" />
      <geometry>
        <mesh
          filename="package://robotic_arm_description/meshes/link_3.STL" />
      </geometry>
      <material
        name="">
        <color
          rgba="0.79216 0.81961 0.93333 1" />
      </material>
    </visual>
    <collision>
      <origin
        xyz="0 0 0"
        rpy="0 0 0" />
      <geometry>
        <mesh
          filename="package://robotic_arm_description/meshes/link_3.STL" />
      </geometry>
    </collision>
  </link>
  <joint
    name="joint_3"
    type="continuous">
    <origin
      xyz="0.051117 0 0.04015"
      rpy="0 0 0" />
    <parent
      link="link_2" />
    <child
      link="link_3" />
    <axis
      xyz="0 -1 0" />
  </joint>
  <link
    name="end_effector">
    <inertial>
      <origin
        xyz="0.00022284 -0.020701 -0.014202"
        rpy="0 0 0" />
      <mass
        value="0.015554" />
      <inertia
        ixx="3.0068E-06"
        ixy="-1.0568E-08"
        ixz="2.0515E-07"
        iyy="1.7554E-06"
        iyz="-2.5581E-09"
        izz="1.8545E-06" />
    </inertial>
    <visual>
      <origin
        xyz="0 0 0"
        rpy="0 0 0" />
      <geometry>
        <mesh
          filename="package://robotic_arm_description/meshes/end_effector.STL" />
      </geometry>
      <material
        name="">
        <color
          rgba="0.79216 0.81961 0.93333 1" />
      </material>
    </visual>
    <collision>
      <origin
        xyz="0 0 0"
        rpy="0 0 0" />
      <geometry>
        <mesh
          filename="package://robotic_arm_description/meshes/end_effector.STL" />
      </geometry>
    </collision>
  </link>
  <joint
    name="joint_4"
    type="continuous">
    <origin
      xyz="0.058386 0 -0.02"
      rpy="0 0 0" />
    <parent
      link="link_3" />
    <child
      link="end_effector" />
    <axis
      xyz="0 -1 0" />
  </joint>
  <link
    name="gripper">
    <inertial>
      <origin
        xyz="0.01753 -0.0022519 -0.0070303"
        rpy="0 0 0" />
      <mass
        value="0.0008242" />
      <inertia
        ixx="3.0387E-08"
        ixy="-2.3851E-23"
        ixz="5.8982E-23"
        iyy="1.7833E-08"
        iyz="-3.6695E-10"
        izz="1.3103E-08" />
    </inertial>
    <visual>
      <origin
        xyz="0 0 0"
        rpy="0 0 0" />
      <geometry>
        <mesh
          filename="package://robotic_arm_description/meshes/gripper.STL" />
      </geometry>
      <material
        name="">
        <color
          rgba="0.79216 0.81961 0.93333 1" />
      </material>
    </visual>
    <collision>
      <origin
        xyz="0 0 0"
        rpy="0 0 0" />
      <geometry>
        <mesh
          filename="package://robotic_arm_description/meshes/gripper.STL" />
      </geometry>
    </collision>
  </link>
  <joint
    name="joint_5"
    type="continuous">
    <origin
      xyz="0 -0.015925 -0.01717"
      rpy="0 0 0" />
    <parent
      link="end_effector" />
    <child
      link="gripper" />
    <axis
      xyz="-1 0 0" />
  </joint>
  <transmission name="trans_1">
  <type>transmission_interface/SimpleTransmission</type>
  <joint name="joint_1">
    <hardwareInterface>hardware_interface/PositionJointInterface</hardwareInterface>
  </joint>
  <actuator name="motor_1">
    <mechanicalReduction>1</mechanicalReduction>
    <hardwareInterface>hardware_interface/PositionJointInterface</hardwareInterface>
  </actuator>
</transmission>
<transmission name="trans_2">
  <type>transmission_interface/SimpleTransmission</type>
  <joint name="joint_2">
    <hardwareInterface>hardware_interface/PositionJointInterface</hardwareInterface>
  </joint>
  <actuator name="motor_2">
    <mechanicalReduction>1</mechanicalReduction>
    <hardwareInterface>hardware_interface/PositionJointInterface</hardwareInterface>
  </actuator>
</transmission>
<transmission name="trans_3">
  <type>transmission_interface/SimpleTransmission</type>
  <joint name="joint_3">
    <hardwareInterface>hardware_interface/PositionJointInterface</hardwareInterface>
  </joint>
  <actuator name="motor_3">
    <mechanicalReduction>1</mechanicalReduction>
    <hardwareInterface>hardware_interface/PositionJointInterface</hardwareInterface>
  </actuator>
</transmission>
<transmission name="trans_4">
  <type>transmission_interface/SimpleTransmission</type>
  <joint name="joint_4">
    <hardwareInterface>hardware_interface/PositionJointInterface</hardwareInterface>
  </joint>
  <actuator name="motor_4">
    <mechanicalReduction>1</mechanicalReduction>
    <hardwareInterface>hardware_interface/PositionJointInterface</hardwareInterface>
  </actuator>
</transmission>
<transmission name="trans_5">
  <type>transmission_interface/SimpleTransmission</type>
  <joint name="joint_5">
    <hardwareInterface>hardware_interface/PositionJointInterface</hardwareInterface>
  </joint>
  <actuator name="motor_5">
    <mechanicalReduction>1</mechanicalReduction>
    <hardwareInterface>hardware_interface/PositionJointInterface</hardwareInterface>
  </actuator>
</transmission>
<link name="camera_link">
    <inertial>
      <mass value="0.1"/>
      <origin rpy="1.57079  0       0" xyz="0  0  0"/>
      <inertia ixx="0.000016875" ixy="0" ixz="0" iyy="0.00000001" iyz="0" izz="0.000016875"/>
    </inertial>
    <collision name="camera_link_collision">
      <origin rpy="0  0       0" xyz="0  0  0"/>
      <geometry>
        <cylinder length="0.001" radius="0.01"/>
      </geometry>
    </collision>
    <visual name="camera_link_visual">
      <origin rpy="1.57079  0       0" xyz="0  0  0"/>
      <geometry>
        <cylinder length="0.01" radius="0.014"/>
      </geometry>
    </visual>
  </link>

  <joint name="camera_depth_joint" type="fixed">
    <origin xyz="0.18 0 0.2" rpy="0 1.57 3.14"/>
    <parent link="world"/>
    <child link="camera_link"/>
  </joint>
  
<gazebo reference="camera_link">
    <sensor type="depth" name="intelrealsenseD435i">
      <always_on>1</always_on>
      <visualize>true</visualize>
      <camera>
        <horizontal_fov>1.57</horizontal_fov>
        <image>
          <width>640</width>
          <height>480</height>
          <format>R8G8B8</format>
        </image>
        <depth_camera>

        </depth_camera>
        <clip>
          <near>0.1</near>
          <far>100</far>
        </clip>
      </camera>
      <plugin name="intelrealsense" filename="libgazebo_ros_openni_kinect.so">
        <alwaysOn>true</alwaysOn>
        <updateRate>10.0</updateRate>
        <cameraName>camera</cameraName>
        <frameName>camera_depth_frame</frameName>
        <imageTopicName>/camera/color/image_raw</imageTopicName>
        <depthImageTopicName>/camera/depth/image_rect_raw</depthImageTopicName>
        <pointCloudTopicName>depth/points</pointCloudTopicName>
        <cameraInfoTopicName>/camera/color/camera_info</cameraInfoTopicName>
        <depthImageCameraInfoTopicName>/camera/depth/camera_info</depthImageCameraInfoTopicName>
        <pointCloudCutoff>0.2</pointCloudCutoff>
         <pointCloudCutoffMax>10.0</pointCloudCutoffMax>
        <hackBaseline>0.07</hackBaseline>
        <distortionK1>0.0</distortionK1>
        <distortionK2>0.0</distortionK2>
        <distortionK3>0.0</distortionK3>
        <distortionT1>0.0</distortionT1>
        <distortionT2>0.0</distortionT2>
        <CxPrime>0.0</CxPrime>
        <Cx>0.0</Cx>
        <Cy>0.0</Cy>
        <focalLength>0.0</focalLength>
      </plugin>
    </sensor>
  </gazebo>
  <gazebo>
    <plugin name="gazebo_ros_control" filename="libgazebo_ros_control.so">
    <robotNamespace>/arm</robotNamespace>
    <robotSimType>gazebo_ros_control/DefaultRobotHWSim</robotSimType>
    </plugin>
  </gazebo>
</robot>
