<?xml version="1.0" encoding="utf-8"?>
<!-- This URDF was automatically created by SolidWorks to URDF Exporter! Originally created by Stephen Brawner (brawner@gmail.com) 
     Commit Version: 1.6.0-1-g15f4949  Build Version: 1.6.7594.29634
     For more information, please see http://wiki.ros.org/sw_urdf_exporter -->
<robot
  name="robotic_arm_assembly">
  <link
    name="base_link">
    <inertial>
      <origin
        xyz="-9.2558E-09 4.4033E-05 0.0091905"
        rpy="0 0 0" />
      <mass
        value="0.13522" />
      <inertia
        ixx="8.2221E-05"
        ixy="-7.4232E-12"
        ixz="-3.4508E-12"
        iyy="8.2338E-05"
        iyz="5.8286E-08"
        izz="0.00016141" />
    </inertial>
    <visual>
      <origin
        xyz="0 0 0"
        rpy="0 0 0" />
      <geometry>
        <mesh
          filename="package://robotic_arm_description/meshes/base_link.STL" />
      </geometry>
      <material
        name="">
        <color
          rgba="0.79216 0.81961 0.93333 1" />
      </material>
    </visual>
    <collision>
      <origin
        xyz="0 0 0"
        rpy="0 0 0" />
      <geometry>
        <mesh
          filename="package://robotic_arm_description/meshes/base_link.STL" />
      </geometry>
    </collision>
  </link>
  <link
    name="link_1">
    <inertial>
      <origin
        xyz="-0.00022776 5.6582E-11 0.013359"
        rpy="0 0 0" />
      <mass
        value="0.057308" />
      <inertia
        ixx="1.5706E-05"
        ixy="-4.2291E-15"
        ixz="2.5297E-15"
        iyy="1.8881E-05"
        iyz="-6.8636E-12"
        izz="2.6568E-05" />
    </inertial>
    <visual>
      <origin
        xyz="0 0 0"
        rpy="0 0 0" />
      <geometry>
        <mesh
          filename="package://robotic_arm_description/meshes/link_1.STL" />
      </geometry>
      <material
        name="">
        <color
          rgba="0.79216 0.81961 0.93333 1" />
      </material>
    </visual>
    <collision>
      <origin
        xyz="0 0 0"
        rpy="0 0 0" />
      <geometry>
        <mesh
          filename="package://robotic_arm_description/meshes/link_1.STL" />
      </geometry>
    </collision>
  </link>
  <joint
    name="joint_1"
    type="continuous">
    <origin
      xyz="0 0 0.036277"
      rpy="0 0 0" />
    <parent
      link="base_link" />
    <child
      link="link_1" />
    <axis
      xyz="0 0 -1" />
  </joint>
  <link
    name="link_2">
    <inertial>
      <origin
        xyz="-0.0029057 0.0047367 0.012674"
        rpy="0 0 0" />
      <mass
        value="0.0052426" />
      <inertia
        ixx="2.7089E-06"
        ixy="-1.3884E-08"
        ixz="1.7878E-07"
        iyy="1.3985E-06"
        iyz="6.0559E-08"
        izz="1.8842E-06" />
    </inertial>
    <visual>
      <origin
        xyz="0 0 0"
        rpy="0 0 0" />
      <geometry>
        <mesh
          filename="package://robotic_arm_description/meshes/link_2.STL" />
      </geometry>
      <material
        name="">
        <color
          rgba="0.79216 0.81961 0.93333 1" />
      </material>
    </visual>
    <collision>
      <origin
        xyz="0 0 0"
        rpy="0 0 0" />
      <geometry>
        <mesh
          filename="package://robotic_arm_description/meshes/link_2.STL" />
      </geometry>
    </collision>
  </link>
  <joint
    name="joint_2"
    type="continuous">
    <origin
      xyz="-0.00515 0 0.028573"
      rpy="0 0 0" />
    <parent
      link="link_1" />
    <child
      link="link_2" />
    <axis
      xyz="0 -1 0" />
  </joint>
  <link
    name="link_3">
    <inertial>
      <origin
        xyz="0.011787 0.0049253 0.00077678"
        rpy="0 0 0" />
      <mass
        value="0.0032899" />
      <inertia
        ixx="5.2071E-07"
        ixy="-5.0464E-12"
        ixz="-2.8603E-08"
        iyy="1.18E-06"
        iyz="-1.2414E-13"
        izz="1.634E-06" />
    </inertial>
    <visual>
      <origin
        xyz="0 0 0"
        rpy="0 0 0" />
      <geometry>
        <mesh
          filename="package://robotic_arm_description/meshes/link_3.STL" />
      </geometry>
      <material
        name="">
        <color
          rgba="0.79216 0.81961 0.93333 1" />
      </material>
    </visual>
    <collision>
      <origin
        xyz="0 0 0"
        rpy="0 0 0" />
      <geometry>
        <mesh
          filename="package://robotic_arm_description/meshes/link_3.STL" />
      </geometry>
    </collision>
  </link>
  <joint
    name="joint_3"
    type="continuous">
    <origin
      xyz="-0.0070261 0 0.039378"
      rpy="0 0 0" />
    <parent
      link="link_2" />
    <child
      link="link_3" />
    <axis
      xyz="0 1 0" />
  </joint>
  <link
    name="end_effector">
    <inertial>
      <origin
        xyz="0.0056397 0.0054334 -0.010942"
        rpy="0 0 0" />
      <mass
        value="0.015759" />
      <inertia
        ixx="2.1781E-06"
        ixy="-9.8765E-09"
        ixz="8.6878E-08"
        iyy="1.1152E-06"
        iyz="-5.5522E-10"
        izz="1.371E-06" />
    </inertial>
    <visual>
      <origin
        xyz="0 0 0"
        rpy="0 0 0" />
      <geometry>
        <mesh
          filename="package://robotic_arm_description/meshes/end_effector.STL" />
      </geometry>
      <material
        name="">
        <color
          rgba="0.79216 0.81961 0.93333 1" />
      </material>
    </visual>
    <collision>
      <origin
        xyz="0 0 0"
        rpy="0 0 0" />
      <geometry>
        <mesh
          filename="package://robotic_arm_description/meshes/end_effector.STL" />
      </geometry>
    </collision>
  </link>
  <joint
    name="joint_4"
    type="fixed">
    <origin
      xyz="0.044 0 1.134E-05"
      rpy="0 0 0" />
    <parent
      link="link_3" />
    <child
      link="end_effector" />
    <axis
      xyz="0 -1 0" />
  </joint>
</robot>